Workbook

Sheet Prix des produits et services 
C1: Nom du produit ou service | D1: Prix année 1 | E1: Prix année 2 | F1: Prix année 3 | G1: Prix année 4 | H1: Prix année 5 | I1: Prix année 6 | J1: Prix année 7
B2: Produit ou Service 1 | C2: Habits | D2: 35000 | E2: 35000 | F2: 40000 | J2: 5500
B3: Produit ou Service 2 | J3: 800
B4: Produit ou Service 3 | J4: 0.2
B5: Produit ou Service 4
B6: Produit ou Service 5
B7: Produit ou Service 6
B8: Produit ou Service 7
B9: Produit ou Service 8
B10: Produit ou Service 9
B11: Produit ou Service 10
B12: Produit ou Service 11
B13: Produit ou Service 12
B14: Produit ou Service 13
B15: Produit ou Service 14
B16: Produit ou Service 15
... B21: Produit ou Service 20
B24: Cout d'achat unitaire | C24: Régime de bananes | D24: 1000 | E24: 1500 | F24: 2000 | G24: 2500 | H24: 2700 | I24: 3000 | J24: 3200
C25: Mangue | D25: 150 | E25: 175 | F25: 200 | G25: 250 | H25: 300 | I25: 325 | J25: 350
C26: Poire | D26: 150 | E26: 175 | F26: 200 | G26: 250 | H26: 300 | I26: 325 | J26: 350

Sheet Calcul intermédiaire 

Sheet Objectifs de ventes (quantité)
B1: Nom du produit ou du service | C1: Mois 1 | D1: Mois 2 | E1: Mois 3 | F1: Mois 4 | G1: Mois 5 | H1: Mois 6 | I1: Mois 7 | J1: Mois 8 | K1: Mois 9 | L1: Mois 10 | M1: Mois 11 | N1: Mois 12 | O1: Année 1 | P1: Mois 13 | Q1: Mois 14 | R1: Mois 15 | S1: Mois 16 | T1: Mois 17 | U1: Mois 18 | V1: Mois 19 | W1: Mois 20 | X1: Mois 21 | Y1: Mois 22 | Z1: Mois 23 | AA1: Mois 24 | AB1: Année 2 | AC1: Mois 25 | AD1: Mois 26 | AE1: Mois 27 | AF1: Mois 28 | AG1: Mois 29 | AH1: Mois 30 | AI1: Mois 31 | AJ1: Mois 32 | AK1: Mois 33 | AL1: Mois 34 | AM1: Mois 35 | AN1: Mois 36 | AO1: Année 3 | AP1: Mois 37 | AQ1: Mois 38 | AR1: Mois 39 | AS1: Mois 40 | AT1: Mois 41 | AU1: Mois 42 | AV1: Mois 43 | AW1: Mois 44 | AX1: Mois 45 | AY1: Mois 46 | AZ1: Mois 47 | BA1: Mois 48 | BB1: Année 4 | BC1: Mois 49 | BD1: Mois 50 | BE1: Mois 51 | BF1: Mois 52 | BG1: Mois 53 | BH1: Mois 54 | BI1: Mois 55 | BJ1: Mois 56 | BK1: Mois 57 | BL1: Mois 58 | BM1: Mois 59 | BN1: Mois 60 | BO1: Année 5 | BP1: Mois 61 | BQ1: Mois 62 | BR1: Mois 63 | BS1: Mois 64 | BT1: Mois 65 | BU1: Mois 66 | BV1: Mois 67 | BW1: Mois 68 | BX1: Mois 69 | BY1: Mois 70 | BZ1: Mois 71 | CA1: Mois 72 | CB1: Année 6 | CC1: Mois 73 | CD1: Mois 74 | CE1: Mois 75 | CF1: Mois 76 | CG1: Mois 77 | CH1: Mois 78 | CI1: Mois 79 | CJ1: Mois 80 | CK1: Mois 81 | CL1: Mois 82 | CM1: Mois 83 | CN1: Mois 84 | CO1: Année 7
A2: ='Prix des produits et services '!B2 -> Produit ou Service 1 | B2: ='Prix des produits et services '!C2 -> Habits | C2: 5 | D2: 10 | E2: 15 | F2: 20 | G2: 25 | H2: 30 | I2: 40 | J2: 45 | K2: 45 | L2: 45 | M2: 45 | N2: 45 | O2: =SUM(C2:N2) -> 370 | P2: 50 | Q2: 55 | R2: 60 | S2: 65 | T2: 70 | U2: 75 | V2: 80 | W2: 85 | X2: 90 | Y2: 95 | Z2: 100 | AA2: 110 | AB2: =SUM(P2:AA2) -> 935 | AC2: 130 | AD2: =AC2*1.01 -> 131.3 | AE2: =AD2*1.01 -> 132.613 | AF2: =AE2*1.01 -> 133.93913 | AG2: =AF2*1.01 -> 135.27852 | AH2: =AG2*1.01 -> 136.63131 | AI2: =AH2*1.01 -> 137.99762 | AJ2: =AI2*1.01 -> 139.3776 | AK2: =AJ2*1.01 -> 140.77137 | ... AN2: =AM2*1.01 -> 145.03689 | AO2: =SUM(AC2:AN2) -> 1648.7254 | AP2: =AN2*1.03 -> 149.38799 | AQ2: =AO2*1.03 -> 1698.1872 | AR2: =AP2*1.03 -> 153.86963 | AS2: =AQ2*1.03 -> 1749.1328 | AT2: =AR2*1.03 -> 158.48572 | AU2: =AS2*1.03 -> 1801.6068 | AV2: =AT2*1.03 -> 163.24029 | AW2: =AU2*1.03 -> 1855.655 | ... BA2: =AY2*1.03 -> 1968.6643 | BB2: =SUM(AP2:BA2) -> 11950.873 | BC2: =BA2*1.03 -> 2027.7243 | BD2: =BB2*1.03 -> 12309.4 | BE2: =BC2*1.03 -> 2088.556 | BF2: =BD2*1.03 -> 12678.682 | BG2: =BE2*1.03 -> 2151.2127 | BH2: =BF2*1.03 -> 13059.042 | BI2: =BG2*1.03 -> 2215.7491 | BJ2: =BH2*1.03 -> 13450.813 | ... BN2: =BL2*1.03 -> 14269.968 | BO2: =SUM(BC2:BN2) -> 92738.393 | BP2: =BN2*1.03 -> 14698.067 | BQ2: =BO2*1.03 -> 95520.545 | BR2: =BP2*1.03 -> 15139.009 | BS2: =BQ2*1.03 -> 98386.161 | BT2: =BR2*1.03 -> 15593.179 | BU2: =BS2*1.03 -> 101337.75 | BV2: =BT2*1.03 -> 16060.974 | BW2: =BU2*1.03 -> 104377.88 | ... CA2: =BY2*1.03 -> 110734.49 | CB2: =SUM(BP2:CA2) -> 712939.16 | CC2: =CA2*1.03 -> 114056.53 | CD2: =CB2*1.03 -> 734327.33 | CE2: =CC2*1.03 -> 117478.22 | CF2: =CD2*1.03 -> 756357.15 | CG2: =CE2*1.03 -> 121002.57 | CH2: =CF2*1.03 -> 779047.87 | CI2: =CG2*1.03 -> 124632.65 | CJ2: =CH2*1.03 -> 802419.3 | ... CN2: =CL2*1.03 -> 851286.64 | CO2: =SUM(CC2:CN2) -> 5487694.5
A3: ='Prix des produits et services '!B3 -> Produit ou Service 2 | B3: ='Prix des produits et services '!C3 -> 0 | O3: =SUM(C3:N3) -> 0 | AB3: =SUM(P3:AA3) -> 0 | AO3: =SUM(AC3:AN3) -> 0 | AP3: =AN3*1.045 -> 0 | AQ3: =AO3*1.045 -> 0 | AR3: =AP3*1.045 -> 0 | AS3: =AQ3*1.045 -> 0 | AT3: =AR3*1.045 -> 0 | AU3: =AS3*1.045 -> 0 | AV3: =AT3*1.045 -> 0 | AW3: =AU3*1.045 -> 0 | ... BA3: =AY3*1.045 -> 0 | BB3: =SUM(AP3:BA3) -> 0 | BC3: =BA3*1.045 -> 0 | BD3: =BB3*1.045 -> 0 | BE3: =BC3*1.045 -> 0 | BF3: =BD3*1.045 -> 0 | BG3: =BE3*1.045 -> 0 | BH3: =BF3*1.045 -> 0 | BI3: =BG3*1.045 -> 0 | BJ3: =BH3*1.045 -> 0 | ... BN3: =BL3*1.045 -> 0 | BO3: =SUM(BC3:BN3) -> 0 | BP3: =BN3*1.045 -> 0 | BQ3: =BO3*1.045 -> 0 | BR3: =BP3*1.045 -> 0 | BS3: =BQ3*1.045 -> 0 | BT3: =BR3*1.045 -> 0 | BU3: =BS3*1.045 -> 0 | BV3: =BT3*1.045 -> 0 | BW3: =BU3*1.045 -> 0 | ... CA3: =BY3*1.045 -> 0 | CB3: =SUM(BP3:CA3) -> 0 | CC3: =CA3*1.045 -> 0 | CD3: =CB3*1.045 -> 0 | CE3: =CC3*1.045 -> 0 | CF3: =CD3*1.045 -> 0 | CG3: =CE3*1.045 -> 0 | CH3: =CF3*1.045 -> 0 | CI3: =CG3*1.045 -> 0 | CJ3: =CH3*1.045 -> 0 | ... CN3: =CL3*1.045 -> 0 | CO3: =SUM(CC3:CN3) -> 0
A4: ='Prix des produits et services '!B4 -> Produit ou Service 3 | B4: ='Prix des produits et services '!C4 -> 0 | O4: =SUM(C4:N4) -> 0 | AB4: =SUM(P4:AA4) -> 0 | AO4: =SUM(AC4:AN4) -> 0 | AP4: =AN4*1.045 -> 0 | AQ4: =AO4*1.045 -> 0 | AR4: =AP4*1.045 -> 0 | AS4: =AQ4*1.045 -> 0 | AT4: =AR4*1.045 -> 0 | AU4: =AS4*1.045 -> 0 | AV4: =AT4*1.045 -> 0 | AW4: =AU4*1.045 -> 0 | ... BA4: =AY4*1.045 -> 0 | BB4: =SUM(AP4:BA4) -> 0 | BC4: =BA4*1.045 -> 0 | BD4: =BB4*1.045 -> 0 | BE4: =BC4*1.045 -> 0 | BF4: =BD4*1.045 -> 0 | BG4: =BE4*1.045 -> 0 | BH4: =BF4*1.045 -> 0 | BI4: =BG4*1.045 -> 0 | BJ4: =BH4*1.045 -> 0 | ... BN4: =BL4*1.045 -> 0 | BO4: =SUM(BC4:BN4) -> 0 | BP4: =BN4*1.045 -> 0 | BQ4: =BO4*1.045 -> 0 | BR4: =BP4*1.045 -> 0 | BS4: =BQ4*1.045 -> 0 | BT4: =BR4*1.045 -> 0 | BU4: =BS4*1.045 -> 0 | BV4: =BT4*1.045 -> 0 | BW4: =BU4*1.045 -> 0 | ... CA4: =BY4*1.045 -> 0 | CB4: =SUM(BP4:CA4) -> 0 | CC4: =CA4*1.045 -> 0 | CD4: =CB4*1.045 -> 0 | CE4: =CC4*1.045 -> 0 | CF4: =CD4*1.045 -> 0 | CG4: =CE4*1.045 -> 0 | CH4: =CF4*1.045 -> 0 | CI4: =CG4*1.045 -> 0 | CJ4: =CH4*1.045 -> 0 | ... CN4: =CL4*1.045 -> 0 | CO4: =SUM(CC4:CN4) -> 0
A5: ='Prix des produits et services '!B5 -> Produit ou Service 4 | B5: ='Prix des produits et services '!C5 -> 0 | O5: =SUM(C5:N5) -> 0 | AB5: =SUM(P5:AA5) -> 0 | AO5: =SUM(AC5:AN5) -> 0 | BB5: =SUM(AP5:BA5) -> 0 | BO5: =SUM(BC5:BN5) -> 0 | CB5: =SUM(BP5:CA5) -> 0 | CO5: =SUM(CC5:CN5) -> 0
A6: ='Prix des produits et services '!B6 -> Produit ou Service 5 | B6: ='Prix des produits et services '!C6 -> 0 | O6: =SUM(C6:N6) -> 0 | AB6: =SUM(P6:AA6) -> 0 | AO6: =SUM(AC6:AN6) -> 0 | BB6: =SUM(AP6:BA6) -> 0 | BO6: =SUM(BC6:BN6) -> 0 | CB6: =SUM(BP6:CA6) -> 0 | CO6: =SUM(CC6:CN6) -> 0
A7: ='Prix des produits et services '!B7 -> Produit ou Service 6 | B7: ='Prix des produits et services '!C7 -> 0 | O7: =SUM(C7:N7) -> 0 | AB7: =SUM(P7:AA7) -> 0 | AO7: =SUM(AC7:AN7) -> 0 | BB7: =SUM(AP7:BA7) -> 0 | BO7: =SUM(BC7:BN7) -> 0 | CB7: =SUM(BP7:CA7) -> 0 | CO7: =SUM(CC7:CN7) -> 0
A8: ='Prix des produits et services '!B8 -> Produit ou Service 7 | B8: ='Prix des produits et services '!C8 -> 0 | O8: =SUM(C8:N8) -> 0 | AB8: =SUM(P8:AA8) -> 0 | AO8: =SUM(AC8:AN8) -> 0 | BB8: =SUM(AP8:BA8) -> 0 | BO8: =SUM(BC8:BN8) -> 0 | CB8: =SUM(BP8:CA8) -> 0 | CO8: =SUM(CC8:CN8) -> 0
A9: ='Prix des produits et services '!B9 -> Produit ou Service 8 | B9: ='Prix des produits et services '!C9 -> 0 | O9: =SUM(C9:N9) -> 0 | AB9: =SUM(P9:AA9) -> 0 | AO9: =SUM(AC9:AN9) -> 0 | BB9: =SUM(AP9:BA9) -> 0 | BO9: =SUM(BC9:BN9) -> 0 | CB9: =SUM(BP9:CA9) -> 0 | CO9: =SUM(CC9:CN9) -> 0
A10: ='Prix des produits et services '!B10 -> Produit ou Service 9 | B10: ='Prix des produits et services '!C10 -> 0 | O10: =SUM(C10:N10) -> 0 | AB10: =SUM(P10:AA10) -> 0 | AO10: =SUM(AC10:AN10) -> 0 | BB10: =SUM(AP10:BA10) -> 0 | BO10: =SUM(BC10:BN10) -> 0 | CB10: =SUM(BP10:CA10) -> 0 | CO10: =SUM(CC10:CN10) -> 0
A11: ='Prix des produits et services '!B11 -> Produit ou Service 10 | B11: ='Prix des produits et services '!C11 -> 0 | O11: =SUM(C11:N11) -> 0 | AB11: =SUM(P11:AA11) -> 0 | AO11: =SUM(AC11:AN11) -> 0 | BB11: =SUM(AP11:BA11) -> 0 | BO11: =SUM(BC11:BN11) -> 0 | CB11: =SUM(BP11:CA11) -> 0 | CO11: =SUM(CC11:CN11) -> 0
A12: ='Prix des produits et services '!B12 -> Produit ou Service 11 | B12: ='Prix des produits et services '!C12 -> 0 | O12: =SUM(C12:N12) -> 0 | AB12: =SUM(P12:AA12) -> 0 | AO12: =SUM(AC12:AN12) -> 0 | BB12: =SUM(AP12:BA12) -> 0 | BO12: =SUM(BC12:BN12) -> 0 | CB12: =SUM(BP12:CA12) -> 0 | CO12: =SUM(CC12:CN12) -> 0
A13: ='Prix des produits et services '!B13 -> Produit ou Service 12 | B13: ='Prix des produits et services '!C13 -> 0 | O13: =SUM(C13:N13) -> 0 | AB13: =SUM(P13:AA13) -> 0 | AO13: =SUM(AC13:AN13) -> 0 | BB13: =SUM(AP13:BA13) -> 0 | BO13: =SUM(BC13:BN13) -> 0 | CB13: =SUM(BP13:CA13) -> 0 | CO13: =SUM(CC13:CN13) -> 0
A14: ='Prix des produits et services '!B14 -> Produit ou Service 13 | B14: ='Prix des produits et services '!C14 -> 0 | O14: =SUM(C14:N14) -> 0 | AB14: =SUM(P14:AA14) -> 0 | AO14: =SUM(AC14:AN14) -> 0 | BB14: =SUM(AP14:BA14) -> 0 | BO14: =SUM(BC14:BN14) -> 0 | CB14: =SUM(BP14:CA14) -> 0 | CO14: =SUM(CC14:CN14) -> 0
A15: ='Prix des produits et services '!B15 -> Produit ou Service 14 | B15: ='Prix des produits et services '!C15 -> 0 | O15: =SUM(C15:N15) -> 0 | AB15: =SUM(P15:AA15) -> 0 | AO15: =SUM(AC15:AN15) -> 0 | BB15: =SUM(AP15:BA15) -> 0 | BO15: =SUM(BC15:BN15) -> 0 | CB15: =SUM(BP15:CA15) -> 0 | CO15: =SUM(CC15:CN15) -> 0
A16: ='Prix des produits et services '!B16 -> Produit ou Service 15 | B16: ='Prix des produits et services '!C16 -> 0 | O16: =SUM(C16:N16) -> 0 | AB16: =SUM(P16:AA16) -> 0 | AO16: =SUM(AC16:AN16) -> 0 | BB16: =SUM(AP16:BA16) -> 0 | BO16: =SUM(BC16:BN16) -> 0 | CB16: =SUM(BP16:CA16) -> 0 | CO16: =SUM(CC16:CN16) -> 0
... A21: ='Prix des produits et services '!B21 -> Produit ou Service 20 | B21: ='Prix des produits et services '!C21 -> 0 | O21: =SUM(C21:N21) -> 0 | AB21: =SUM(P21:AA21) -> 0 | AO21: =SUM(AC21:AN21) -> 0 | BB21: =SUM(AP21:BA21) -> 0 | BO21: =SUM(BC21:BN21) -> 0 | CB21: =SUM(BP21:CA21) -> 0 | CO21: =SUM(CC21:CN21) -> 0

Sheet Chiffre d'affaires prévisionnel
B1: Nom du produit ou du service | C1: Mois 1 | D1: Mois 2 | E1: Mois 3 | F1: Mois 4 | G1: Mois 5 | H1: Mois 6 | I1: Mois 7 | J1: Mois 8 | K1: Mois 9 | L1: Mois 10 | M1: Mois 11 | N1: Mois 12 | O1: Année 1 | P1: Mois 13 | Q1: Mois 14 | R1: Mois 15 | S1: Mois 16 | T1: Mois 17 | U1: Mois 18 | V1: Mois 19 | W1: Mois 20 | X1: Mois 21 | Y1: Mois 22 | Z1: Mois 23 | AA1: Mois 24 | AB1: Année 2 | AC1: Mois 25 | AD1: Mois 26 | AE1: Mois 27 | AF1: Mois 28 | AG1: Mois 29 | AH1: Mois 30 | AI1: Mois 31 | AJ1: Mois 32 | AK1: Mois 33 | AL1: Mois 34 | AM1: Mois 35 | AN1: Mois 36 | AO1: Année 3 | AP1: Mois 37 | AQ1: Mois 38 | AR1: Mois 39 | AS1: Mois 40 | AT1: Mois 41 | AU1: Mois 42 | AV1: Mois 43 | AW1: Mois 44 | AX1: Mois 45 | AY1: Mois 46 | AZ1: Mois 47 | BA1: Mois 48 | BB1: Année 4 | BC1: Mois 49 | BD1: Mois 50 | BE1: Mois 51 | BF1: Mois 52 | BG1: Mois 53 | BH1: Mois 54 | BI1: Mois 55 | BJ1: Mois 56 | BK1: Mois 57 | BL1: Mois 58 | BM1: Mois 59 | BN1: Mois 60 | BO1: Année 5
A2: ='Prix des produits et services '!B2 -> Produit ou Service 1 | B2: ='Prix des produits et services '!C2 -> Habits | C2: ='Prix des produits et services '!$D$2*'Objectifs de ventes (quantité)'!C2 -> 175000 | D2: ='Prix des produits et services '!$D$2*'Objectifs de ventes (quantité)'!D2 -> 350000 | E2: ='Prix des produits et services '!$D$2*'Objectifs de ventes (quantité)'!E2 -> 525000 | F2: ='Prix des produits et services '!$D$2*'Objectifs de ventes (quantité)'!F2 -> 700000 | G2: ='Prix des produits et services '!$D$2*'Objectifs de ventes (quantité)'!G2 -> 875000 | H2: ='Prix des produits et services '!$D$2*'Objectifs de ventes (quantité)'!H2 -> 1050000 | I2: ='Prix des produits et services '!$D$2*'Objectifs de ventes (quantité)'!I2 -> 1400000 | J2: ='Prix des produits et services '!$D$2*'Objectifs de ventes (quantité)'!J2 -> 1575000 | ... N2: ='Prix des produits et services '!$D$2*'Objectifs de ventes (quantité)'!N2 -> 1575000 | O2: =SUM(C2:N2) -> 12950000 | P2: ='Prix des produits et services '!$E$2*'Objectifs de ventes (quantité)'!P2 -> 1750000 | Q2: ='Prix des produits et services '!$E$2*'Objectifs de ventes (quantité)'!Q2 -> 1925000 | R2: ='Prix des produits et services '!$E$2*'Objectifs de ventes (quantité)'!R2 -> 2100000 | S2: ='Prix des produits et services '!$E$2*'Objectifs de ventes (quantité)'!S2 -> 2275000 | T2: ='Prix des produits et services '!$E$2*'Objectifs de ventes (quantité)'!T2 -> 2450000 | U2: ='Prix des produits et services '!$E$2*'Objectifs de ventes (quantité)'!U2 -> 2625000 | V2: ='Prix des produits et services '!$E$2*'Objectifs de ventes (quantité)'!V2 -> 2800000 | W2: ='Prix des produits et services '!$E$2*'Objectifs de ventes (quantité)'!W2 -> 2975000 | ... AA2: ='Prix des produits et services '!$E$2*'Objectifs de ventes (quantité)'!AA2 -> 3850000 | AB2: =SUM(P2:AA2) -> 32725000 | AC2: ='Prix des produits et services '!F2*'Objectifs de ventes (quantité)'!AC2 -> 5200000 | AD2: ='Prix des produits et services '!$F$2*'Objectifs de ventes (quantité)'!AD2 -> 5252000 | AE2: ='Prix des produits et services '!$F$2*'Objectifs de ventes (quantité)'!AE2 -> 5304520 | AF2: ='Prix des produits et services '!$F$2*'Objectifs de ventes (quantité)'!AF2 -> 5357565.2 | AG2: ='Prix des produits et services '!$F$2*'Objectifs de ventes (quantité)'!AG2 -> 5411140.9 | AH2: ='Prix des produits et services '!$F$2*'Objectifs de ventes (quantité)'!AH2 -> 5465252.3 | AI2: ='Prix des produits et services '!$F$2*'Objectifs de ventes (quantité)'!AI2 -> 5519904.8 | AJ2: ='Prix des produits et services '!$F$2*'Objectifs de ventes (quantité)'!AJ2 -> 5575103.8 | AK2: ='Prix des produits et services '!$F$2*'Objectifs de ventes (quantité)'!AK2 -> 5630854.9 | ... AN2: ='Prix des produits et services '!$F$2*'Objectifs de ventes (quantité)'!AN2 -> 5801475.4 | AO2: =SUM(AC2:AN2) -> 65949016 | AP2: ='Prix des produits et services '!$G$2*'Objectifs de ventes (quantité)'!AP2 -> 0 | AQ2: ='Prix des produits et services '!$G$2*'Objectifs de ventes (quantité)'!AQ2 -> 0 | AR2: ='Prix des produits et services '!$G$2*'Objectifs de ventes (quantité)'!AR2 -> 0 | AS2: ='Prix des produits et services '!$G$2*'Objectifs de ventes (quantité)'!AS2 -> 0 | AT2: ='Prix des produits et services '!$G$2*'Objectifs de ventes (quantité)'!AT2 -> 0 | AU2: ='Prix des produits et services '!$G$2*'Objectifs de ventes (quantité)'!AU2 -> 0 | AV2: ='Prix des produits et services '!$G$2*'Objectifs de ventes (quantité)'!AV2 -> 0 | AW2: ='Prix des produits et services '!$G$2*'Objectifs de ventes (quantité)'!AW2 -> 0 | ... BA2: ='Prix des produits et services '!$G$2*'Objectifs de ventes (quantité)'!BA2 -> 0 | BB2: =SUM(AP2:BA2) -> 0 | BC2: ='Prix des produits et services '!$H$2*'Objectifs de ventes (quantité)'!BC2 -> 0 | BD2: ='Prix des produits et services '!$H$2*'Objectifs de ventes (quantité)'!BD2 -> 0 | BE2: ='Prix des produits et services '!$H$2*'Objectifs de ventes (quantité)'!BE2 -> 0 | BF2: ='Prix des produits et services '!$H$2*'Objectifs de ventes (quantité)'!BF2 -> 0 | BG2: ='Prix des produits et services '!$H$2*'Objectifs de ventes (quantité)'!BG2 -> 0 | BH2: ='Prix des produits et services '!$H$2*'Objectifs de ventes (quantité)'!BH2 -> 0 | BI2: ='Prix des produits et services '!$H$2*'Objectifs de ventes (quantité)'!BI2 -> 0 | BJ2: ='Prix des produits et services '!$H$2*'Objectifs de ventes (quantité)'!BJ2 -> 0 | ... BN2: ='Prix des produits et services '!$H$2*'Objectifs de ventes (quantité)'!BN2 -> 0 | BO2: =SUM(BC2:BN2) -> 0
A3: ='Prix des produits et services '!B3 -> Produit ou Service 2 | B3: ='Prix des produits et services '!C3 -> 0 | C3: ='Prix des produits et services '!$D$3*'Objectifs de ventes (quantité)'!C3 -> 0 | D3: ='Prix des produits et services '!$D$3*'Objectifs de ventes (quantité)'!D3 -> 0 | E3: ='Prix des produits et services '!$D$3*'Objectifs de ventes (quantité)'!E3 -> 0 | F3: ='Prix des produits et services '!$D$3*'Objectifs de ventes (quantité)'!F3 -> 0 | G3: ='Prix des produits et services '!$D$3*'Objectifs de ventes (quantité)'!G3 -> 0 | H3: ='Prix des produits et services '!$D$3*'Objectifs de ventes (quantité)'!H3 -> 0 | I3: ='Prix des produits et services '!$D$3*'Objectifs de ventes (quantité)'!I3 -> 0 | J3: ='Prix des produits et services '!$D$3*'Objectifs de ventes (quantité)'!J3 -> 0 | ... N3: ='Prix des produits et services '!$D$3*'Objectifs de ventes (quantité)'!N3 -> 0 | O3: =SUM(C3:N3) -> 0 | P3: ='Prix des produits et services '!$E$3*'Objectifs de ventes (quantité)'!P3 -> 0 | Q3: ='Prix des produits et services '!$E$3*'Objectifs de ventes (quantité)'!Q3 -> 0 | R3: ='Prix des produits et services '!$E$3*'Objectifs de ventes (quantité)'!R3 -> 0 | S3: ='Prix des produits et services '!$E$3*'Objectifs de ventes (quantité)'!S3 -> 0 | T3: ='Prix des produits et services '!$E$3*'Objectifs de ventes (quantité)'!T3 -> 0 | U3: ='Prix des produits et services '!$E$3*'Objectifs de ventes (quantité)'!U3 -> 0 | V3: ='Prix des produits et services '!$E$3*'Objectifs de ventes (quantité)'!V3 -> 0 | W3: ='Prix des produits et services '!$E$3*'Objectifs de ventes (quantité)'!W3 -> 0 | ... AA3: ='Prix des produits et services '!$E$3*'Objectifs de ventes (quantité)'!AA3 -> 0 | AB3: =SUM(P3:AA3) -> 0 | AC3: ='Prix des produits et services '!$F$3*'Objectifs de ventes (quantité)'!AC3 -> 0 | AD3: ='Prix des produits et services '!$F$3*'Objectifs de ventes (quantité)'!AD3 -> 0 | AE3: ='Prix des produits et services '!$F$3*'Objectifs de ventes (quantité)'!AE3 -> 0 | AF3: ='Prix des produits et services '!$F$3*'Objectifs de ventes (quantité)'!AF3 -> 0 | AG3: ='Prix des produits et services '!$F$3*'Objectifs de ventes (quantité)'!AG3 -> 0 | AH3: ='Prix des produits et services '!$F$3*'Objectifs de ventes (quantité)'!AH3 -> 0 | AI3: ='Prix des produits et services '!$F$3*'Objectifs de ventes (quantité)'!AI3 -> 0 | AJ3: ='Prix des produits et services '!$F$3*'Objectifs de ventes (quantité)'!AJ3 -> 0 | ... AN3: ='Prix des produits et services '!$F$3*'Objectifs de ventes (quantité)'!AN3 -> 0 | AO3: =SUM(AC3:AN3) -> 0 | AP3: ='Prix des produits et services '!$G$3*'Objectifs de ventes (quantité)'!AP3 -> 0 | AQ3: ='Prix des produits et services '!$G$3*'Objectifs de ventes (quantité)'!AQ3 -> 0 | AR3: ='Prix des produits et services '!$G$3*'Objectifs de ventes (quantité)'!AR3 -> 0 | AS3: ='Prix des produits et services '!$G$3*'Objectifs de ventes (quantité)'!AS3 -> 0 | AT3: ='Prix des produits et services '!$G$3*'Objectifs de ventes (quantité)'!AT3 -> 0 | AU3: ='Prix des produits et services '!$G$3*'Objectifs de ventes (quantité)'!AU3 -> 0 | AV3: ='Prix des produits et services '!$G$3*'Objectifs de ventes (quantité)'!AV3 -> 0 | AW3: ='Prix des produits et services '!$G$3*'Objectifs de ventes (quantité)'!AW3 -> 0 | ... BA3: ='Prix des produits et services '!$G$3*'Objectifs de ventes (quantité)'!BA3 -> 0 | BB3: =SUM(AP3:BA3) -> 0 | BC3: ='Prix des produits et services '!$H$3*'Objectifs de ventes (quantité)'!BC3 -> 0 | BD3: ='Prix des produits et services '!$H$3*'Objectifs de ventes (quantité)'!BD3 -> 0 | BE3: ='Prix des produits et services '!$H$3*'Objectifs de ventes (quantité)'!BE3 -> 0 | BF3: ='Prix des produits et services '!$H$3*'Objectifs de ventes (quantité)'!BF3 -> 0 | BG3: ='Prix des produits et services '!$H$3*'Objectifs de ventes (quantité)'!BG3 -> 0 | BH3: ='Prix des produits et services '!$H$3*'Objectifs de ventes (quantité)'!BH3 -> 0 | BI3: ='Prix des produits et services '!$H$3*'Objectifs de ventes (quantité)'!BI3 -> 0 | BJ3: ='Prix des produits et services '!$H$3*'Objectifs de ventes (quantité)'!BJ3 -> 0 | ... BN3: ='Prix des produits et services '!$H$3*'Objectifs de ventes (quantité)'!BN3 -> 0 | BO3: =SUM(BC3:BN3) -> 0
A4: ='Prix des produits et services '!B4 -> Produit ou Service 3 | B4: ='Prix des produits et services '!C4 -> 0 | C4: ='Prix des produits et services '!$D$4*'Objectifs de ventes (quantité)'!C4 -> 0 | D4: ='Prix des produits et services '!$D$4*'Objectifs de ventes (quantité)'!D4 -> 0 | E4: ='Prix des produits et services '!$D$4*'Objectifs de ventes (quantité)'!E4 -> 0 | F4: ='Prix des produits et services '!$D$4*'Objectifs de ventes (quantité)'!F4 -> 0 | G4: ='Prix des produits et services '!$D$4*'Objectifs de ventes (quantité)'!G4 -> 0 | H4: ='Prix des produits et services '!$D$4*'Objectifs de ventes (quantité)'!H4 -> 0 | I4: ='Prix des produits et services '!$D$4*'Objectifs de ventes (quantité)'!I4 -> 0 | J4: ='Prix des produits et services '!$D$4*'Objectifs de ventes (quantité)'!J4 -> 0 | ... N4: ='Prix des produits et services '!$D$4*'Objectifs de ventes (quantité)'!N4 -> 0 | O4: =SUM(C4:N4) -> 0 | P4: ='Prix des produits et services '!$E$4*'Objectifs de ventes (quantité)'!P4 -> 0 | Q4: ='Prix des produits et services '!$E$4*'Objectifs de ventes (quantité)'!Q4 -> 0 | R4: ='Prix des produits et services '!$E$4*'Objectifs de ventes (quantité)'!R4 -> 0 | S4: ='Prix des produits et services '!$E$4*'Objectifs de ventes (quantité)'!S4 -> 0 | T4: ='Prix des produits et services '!$E$4*'Objectifs de ventes (quantité)'!T4 -> 0 | U4: ='Prix des produits et services '!$E$4*'Objectifs de ventes (quantité)'!U4 -> 0 | V4: ='Prix des produits et services '!$E$4*'Objectifs de ventes (quantité)'!V4 -> 0 | W4: ='Prix des produits et services '!$E$4*'Objectifs de ventes (quantité)'!W4 -> 0 | ... AA4: ='Prix des produits et services '!$E$4*'Objectifs de ventes (quantité)'!AA4 -> 0 | AB4: =SUM(P4:AA4) -> 0 | AC4: ='Prix des produits et services '!$F$4*'Objectifs de ventes (quantité)'!AC4 -> 0 | AD4: ='Prix des produits et services '!$F$4*'Objectifs de ventes (quantité)'!AD4 -> 0 | AE4: ='Prix des produits et services '!$F$4*'Objectifs de ventes (quantité)'!AE4 -> 0 | AF4: ='Prix des produits et services '!$F$4*'Objectifs de ventes (quantité)'!AF4 -> 0 | AG4: ='Prix des produits et services '!$F$4*'Objectifs de ventes (quantité)'!AG4 -> 0 | AH4: ='Prix des produits et services '!$F$4*'Objectifs de ventes (quantité)'!AH4 -> 0 | AI4: ='Prix des produits et services '!$F$4*'Objectifs de ventes (quantité)'!AI4 -> 0 | AJ4: ='Prix des produits et services '!$F$4*'Objectifs de ventes (quantité)'!AJ4 -> 0 | ... AN4: ='Prix des produits et services '!$F$4*'Objectifs de ventes (quantité)'!AN4 -> 0 | AO4: =SUM(AC4:AN4) -> 0 | AP4: ='Prix des produits et services '!$G$4*'Objectifs de ventes (quantité)'!AP4 -> 0 | AQ4: ='Prix des produits et services '!$G$4*'Objectifs de ventes (quantité)'!AQ4 -> 0 | AR4: ='Prix des produits et services '!$G$4*'Objectifs de ventes (quantité)'!AR4 -> 0 | AS4: ='Prix des produits et services '!$G$4*'Objectifs de ventes (quantité)'!AS4 -> 0 | AT4: ='Prix des produits et services '!$G$4*'Objectifs de ventes (quantité)'!AT4 -> 0 | AU4: ='Prix des produits et services '!$G$4*'Objectifs de ventes (quantité)'!AU4 -> 0 | AV4: ='Prix des produits et services '!$G$4*'Objectifs de ventes (quantité)'!AV4 -> 0 | AW4: ='Prix des produits et services '!$G$4*'Objectifs de ventes (quantité)'!AW4 -> 0 | ... BA4: ='Prix des produits et services '!$G$4*'Objectifs de ventes (quantité)'!BA4 -> 0 | BB4: =SUM(AP4:BA4) -> 0 | BC4: ='Prix des produits et services '!$H$4*'Objectifs de ventes (quantité)'!BC4 -> 0 | BD4: ='Prix des produits et services '!$H$4*'Objectifs de ventes (quantité)'!BD4 -> 0 | BE4: ='Prix des produits et services '!$H$4*'Objectifs de ventes (quantité)'!BE4 -> 0 | BF4: ='Prix des produits et services '!$H$4*'Objectifs de ventes (quantité)'!BF4 -> 0 | BG4: ='Prix des produits et services '!$H$4*'Objectifs de ventes (quantité)'!BG4 -> 0 | BH4: ='Prix des produits et services '!$H$4*'Objectifs de ventes (quantité)'!BH4 -> 0 | BI4: ='Prix des produits et services '!$H$4*'Objectifs de ventes (quantité)'!BI4 -> 0 | BJ4: ='Prix des produits et services '!$H$4*'Objectifs de ventes (quantité)'!BJ4 -> 0 | ... BN4: ='Prix des produits et services '!$H$4*'Objectifs de ventes (quantité)'!BN4 -> 0 | BO4: =SUM(BC4:BN4) -> 0
A5: ='Prix des produits et services '!B5 -> Produit ou Service 4 | B5: ='Prix des produits et services '!C5 -> 0 | C5: ='Prix des produits et services '!$D$5*'Objectifs de ventes (quantité)'!C5 -> 0 | D5: ='Prix des produits et services '!$D$5*'Objectifs de ventes (quantité)'!D5 -> 0 | E5: ='Prix des produits et services '!$D$5*'Objectifs de ventes (quantité)'!E5 -> 0 | F5: ='Prix des produits et services '!$D$5*'Objectifs de ventes (quantité)'!F5 -> 0 | G5: ='Prix des produits et services '!$D$5*'Objectifs de ventes (quantité)'!G5 -> 0 | H5: ='Prix des produits et services '!$D$5*'Objectifs de ventes (quantité)'!H5 -> 0 | I5: ='Prix des produits et services '!$D$5*'Objectifs de ventes (quantité)'!I5 -> 0 | J5: ='Prix des produits et services '!$D$5*'Objectifs de ventes (quantité)'!J5 -> 0 | ... N5: ='Prix des produits et services '!$D$5*'Objectifs de ventes (quantité)'!N5 -> 0 | O5: =SUM(C5:N5) -> 0 | P5: ='Prix des produits et services '!$E$5*'Objectifs de ventes (quantité)'!P5 -> 0 | Q5: ='Prix des produits et services '!$E$5*'Objectifs de ventes (quantité)'!Q5 -> 0 | R5: ='Prix des produits et services '!$E$5*'Objectifs de ventes (quantité)'!R5 -> 0 | S5: ='Prix des produits et services '!$E$5*'Objectifs de ventes (quantité)'!S5 -> 0 | T5: ='Prix des produits et services '!$E$5*'Objectifs de ventes (quantité)'!T5 -> 0 | U5: ='Prix des produits et services '!$E$5*'Objectifs de ventes (quantité)'!U5 -> 0 | V5: ='Prix des produits et services '!$E$5*'Objectifs de ventes (quantité)'!V5 -> 0 | W5: ='Prix des produits et services '!$E$5*'Objectifs de ventes (quantité)'!W5 -> 0 | ... AA5: ='Prix des produits et services '!$E$5*'Objectifs de ventes (quantité)'!AA5 -> 0 | AB5: =SUM(P5:AA5) -> 0 | AC5: ='Prix des produits et services '!$F$5*'Objectifs de ventes (quantité)'!AC5 -> 0 | AD5: ='Prix des produits et services '!$F$5*'Objectifs de ventes (quantité)'!AD5 -> 0 | AE5: ='Prix des produits et services '!$F$5*'Objectifs de ventes (quantité)'!AE5 -> 0 | AF5: ='Prix des produits et services '!$F$5*'Objectifs de ventes (quantité)'!AF5 -> 0 | AG5: ='Prix des produits et services '!$F$5*'Objectifs de ventes (quantité)'!AG5 -> 0 | AH5: ='Prix des produits et services '!$F$5*'Objectifs de ventes (quantité)'!AH5 -> 0 | AI5: ='Prix des produits et services '!$F$5*'Objectifs de ventes (quantité)'!AI5 -> 0 | AJ5: ='Prix des produits et services '!$F$5*'Objectifs de ventes (quantité)'!AJ5 -> 0 | ... AN5: ='Prix des produits et services '!$F$5*'Objectifs de ventes (quantité)'!AN5 -> 0 | AO5: =SUM(AC5:AN5) -> 0 | AP5: ='Prix des produits et services '!$G$5*'Objectifs de ventes (quantité)'!AP5 -> 0 | AQ5: ='Prix des produits et services '!$G$5*'Objectifs de ventes (quantité)'!AQ5 -> 0 | AR5: ='Prix des produits et services '!$G$5*'Objectifs de ventes (quantité)'!AR5 -> 0 | AS5: ='Prix des produits et services '!$G$5*'Objectifs de ventes (quantité)'!AS5 -> 0 | AT5: ='Prix des produits et services '!$G$5*'Objectifs de ventes (quantité)'!AT5 -> 0 | AU5: ='Prix des produits et services '!$G$5*'Objectifs de ventes (quantité)'!AU5 -> 0 | AV5: ='Prix des produits et services '!$G$5*'Objectifs de ventes (quantité)'!AV5 -> 0 | AW5: ='Prix des produits et services '!$G$5*'Objectifs de ventes (quantité)'!AW5 -> 0 | ... BA5: ='Prix des produits et services '!$G$5*'Objectifs de ventes (quantité)'!BA5 -> 0 | BB5: =SUM(AP5:BA5) -> 0 | BC5: ='Prix des produits et services '!$H$5*'Objectifs de ventes (quantité)'!BC5 -> 0 | BD5: ='Prix des produits et services '!$H$5*'Objectifs de ventes (quantité)'!BD5 -> 0 | BE5: ='Prix des produits et services '!$H$5*'Objectifs de ventes (quantité)'!BE5 -> 0 | BF5: ='Prix des produits et services '!$H$5*'Objectifs de ventes (quantité)'!BF5 -> 0 | BG5: ='Prix des produits et services '!$H$5*'Objectifs de ventes (quantité)'!BG5 -> 0 | BH5: ='Prix des produits et services '!$H$5*'Objectifs de ventes (quantité)'!BH5 -> 0 | BI5: ='Prix des produits et services '!$H$5*'Objectifs de ventes (quantité)'!BI5 -> 0 | BJ5: ='Prix des produits et services '!$H$5*'Objectifs de ventes (quantité)'!BJ5 -> 0 | ... BN5: ='Prix des produits et services '!$H$5*'Objectifs de ventes (quantité)'!BN5 -> 0 | BO5: =SUM(BC5:BN5) -> 0
A6: ='Prix des produits et services '!B6 -> Produit ou Service 5 | B6: ='Prix des produits et services '!C6 -> 0 | C6: ='Prix des produits et services '!$D$6*'Objectifs de ventes (quantité)'!C6 -> 0 | D6: ='Prix des produits et services '!$D$6*'Objectifs de ventes (quantité)'!D6 -> 0 | E6: ='Prix des produits et services '!$D$6*'Objectifs de ventes (quantité)'!E6 -> 0 | F6: ='Prix des produits et services '!$D$6*'Objectifs de ventes (quantité)'!F6 -> 0 | G6: ='Prix des produits et services '!$D$6*'Objectifs de ventes (quantité)'!G6 -> 0 | H6: ='Prix des produits et services '!$D$6*'Objectifs de ventes (quantité)'!H6 -> 0 | I6: ='Prix des produits et services '!$D$6*'Objectifs de ventes (quantité)'!I6 -> 0 | J6: ='Prix des produits et services '!$D$6*'Objectifs de ventes (quantité)'!J6 -> 0 | ... N6: ='Prix des produits et services '!$D$6*'Objectifs de ventes (quantité)'!N6 -> 0 | O6: =SUM(C6:N6) -> 0 | P6: ='Prix des produits et services '!$E$6*'Objectifs de ventes (quantité)'!P6 -> 0 | Q6: ='Prix des produits et services '!$E$6*'Objectifs de ventes (quantité)'!Q6 -> 0 | R6: ='Prix des produits et services '!$E$6*'Objectifs de ventes (quantité)'!R6 -> 0 | S6: ='Prix des produits et services '!$E$6*'Objectifs de ventes (quantité)'!S6 -> 0 | T6: ='Prix des produits et services '!$E$6*'Objectifs de ventes (quantité)'!T6 -> 0 | U6: ='Prix des produits et services '!$E$6*'Objectifs de ventes (quantité)'!U6 -> 0 | V6: ='Prix des produits et services '!$E$6*'Objectifs de ventes (quantité)'!V6 -> 0 | W6: ='Prix des produits et services '!$E$6*'Objectifs de ventes (quantité)'!W6 -> 0 | ... AA6: ='Prix des produits et services '!$E$6*'Objectifs de ventes (quantité)'!AA6 -> 0 | AB6: =SUM(P6:AA6) -> 0 | AC6: ='Prix des produits et services '!$F$6*'Objectifs de ventes (quantité)'!AC6 -> 0 | AD6: ='Prix des produits et services '!$F$6*'Objectifs de ventes (quantité)'!AD6 -> 0 | AE6: ='Prix des produits et services '!$F$6*'Objectifs de ventes (quantité)'!AE6 -> 0 | AF6: ='Prix des produits et services '!$F$6*'Objectifs de ventes (quantité)'!AF6 -> 0 | AG6: ='Prix des produits et services '!$F$6*'Objectifs de ventes (quantité)'!AG6 -> 0 | AH6: ='Prix des produits et services '!$F$6*'Objectifs de ventes (quantité)'!AH6 -> 0 | AI6: ='Prix des produits et services '!$F$6*'Objectifs de ventes (quantité)'!AI6 -> 0 | AJ6: ='Prix des produits et services '!$F$6*'Objectifs de ventes (quantité)'!AJ6 -> 0 | ... AN6: ='Prix des produits et services '!$F$6*'Objectifs de ventes (quantité)'!AN6 -> 0 | AO6: =SUM(AC6:AN6) -> 0 | AP6: ='Prix des produits et services '!$G$6*'Objectifs de ventes (quantité)'!AP6 -> 0 | AQ6: ='Prix des produits et services '!$G$6*'Objectifs de ventes (quantité)'!AQ6 -> 0 | AR6: ='Prix des produits et services '!$G$6*'Objectifs de ventes (quantité)'!AR6 -> 0 | AS6: ='Prix des produits et services '!$G$6*'Objectifs de ventes (quantité)'!AS6 -> 0 | AT6: ='Prix des produits et services '!$G$6*'Objectifs de ventes (quantité)'!AT6 -> 0 | AU6: ='Prix des produits et services '!$G$6*'Objectifs de ventes (quantité)'!AU6 -> 0 | AV6: ='Prix des produits et services '!$G$6*'Objectifs de ventes (quantité)'!AV6 -> 0 | AW6: ='Prix des produits et services '!$G$6*'Objectifs de ventes (quantité)'!AW6 -> 0 | ... BA6: ='Prix des produits et services '!$G$6*'Objectifs de ventes (quantité)'!BA6 -> 0 | BB6: =SUM(AP6:BA6) -> 0 | BC6: ='Prix des produits et services '!$H$6*'Objectifs de ventes (quantité)'!BC6 -> 0 | BD6: ='Prix des produits et services '!$H$6*'Objectifs de ventes (quantité)'!BD6 -> 0 | BE6: ='Prix des produits et services '!$H$6*'Objectifs de ventes (quantité)'!BE6 -> 0 | BF6: ='Prix des produits et services '!$H$6*'Objectifs de ventes (quantité)'!BF6 -> 0 | BG6: ='Prix des produits et services '!$H$6*'Objectifs de ventes (quantité)'!BG6 -> 0 | BH6: ='Prix des produits et services '!$H$6*'Objectifs de ventes (quantité)'!BH6 -> 0 | BI6: ='Prix des produits et services '!$H$6*'Objectifs de ventes (quantité)'!BI6 -> 0 | BJ6: ='Prix des produits et services '!$H$6*'Objectifs de ventes (quantité)'!BJ6 -> 0 | ... BN6: ='Prix des produits et services '!$H$6*'Objectifs de ventes (quantité)'!BN6 -> 0 | BO6: =SUM(BC6:BN6) -> 0
A7: ='Prix des produits et services '!B7 -> Produit ou Service 6 | B7: ='Prix des produits et services '!C7 -> 0 | C7: ='Prix des produits et services '!$D$7*'Objectifs de ventes (quantité)'!C7 -> 0 | D7: ='Prix des produits et services '!$D$7*'Objectifs de ventes (quantité)'!D7 -> 0 | E7: ='Prix des produits et services '!$D$7*'Objectifs de ventes (quantité)'!E7 -> 0 | F7: ='Prix des produits et services '!$D$7*'Objectifs de ventes (quantité)'!F7 -> 0 | G7: ='Prix des produits et services '!$D$7*'Objectifs de ventes (quantité)'!G7 -> 0 | H7: ='Prix des produits et services '!$D$7*'Objectifs de ventes (quantité)'!H7 -> 0 | I7: ='Prix des produits et services '!$D$7*'Objectifs de ventes (quantité)'!I7 -> 0 | J7: ='Prix des produits et services '!$D$7*'Objectifs de ventes (quantité)'!J7 -> 0 | ... N7: ='Prix des produits et services '!$D$7*'Objectifs de ventes (quantité)'!N7 -> 0 | O7: =SUM(C7:N7) -> 0 | P7: ='Prix des produits et services '!$E$7*'Objectifs de ventes (quantité)'!P7 -> 0 | Q7: ='Prix des produits et services '!$E$7*'Objectifs de ventes (quantité)'!Q7 -> 0 | R7: ='Prix des produits et services '!$E$7*'Objectifs de ventes (quantité)'!R7 -> 0 | S7: ='Prix des produits et services '!$E$7*'Objectifs de ventes (quantité)'!S7 -> 0 | T7: ='Prix des produits et services '!$E$7*'Objectifs de ventes (quantité)'!T7 -> 0 | U7: ='Prix des produits et services '!$E$7*'Objectifs de ventes (quantité)'!U7 -> 0 | V7: ='Prix des produits et services '!$E$7*'Objectifs de ventes (quantité)'!V7 -> 0 | W7: ='Prix des produits et services '!$E$7*'Objectifs de ventes (quantité)'!W7 -> 0 | ... AA7: ='Prix des produits et services '!$E$7*'Objectifs de ventes (quantité)'!AA7 -> 0 | AB7: =SUM(P7:AA7) -> 0 | AC7: ='Prix des produits et services '!F7*'Objectifs de ventes (quantité)'!AC7 -> 0 | AD7: ='Prix des produits et services '!G7*'Objectifs de ventes (quantité)'!AD7 -> 0 | AE7: ='Prix des produits et services '!H7*'Objectifs de ventes (quantité)'!AE7 -> 0 | AF7: ='Prix des produits et services '!I7*'Objectifs de ventes (quantité)'!AF7 -> 0 | AG7: ='Prix des produits et services '!J7*'Objectifs de ventes (quantité)'!AG7 -> 0 | AH7: ='Prix des produits et services '!K7*'Objectifs de ventes (quantité)'!AH7 -> 0 | AI7: ='Prix des produits et services '!L7*'Objectifs de ventes (quantité)'!AI7 -> 0 | AJ7: ='Prix des produits et services '!M7*'Objectifs de ventes (quantité)'!AJ7 -> 0 | ... AN7: ='Prix des produits et services '!Q7*'Objectifs de ventes (quantité)'!AN7 -> 0 | AO7: =SUM(AC7:AN7) -> 0 | AP7: ='Prix des produits et services '!$G$7*'Objectifs de ventes (quantité)'!AP7 -> 0 | AQ7: ='Prix des produits et services '!$G$7*'Objectifs de ventes (quantité)'!AQ7 -> 0 | AR7: ='Prix des produits et services '!$G$7*'Objectifs de ventes (quantité)'!AR7 -> 0 | AS7: ='Prix des produits et services '!$G$7*'Objectifs de ventes (quantité)'!AS7 -> 0 | AT7: ='Prix des produits et services '!$G$7*'Objectifs de ventes (quantité)'!AT7 -> 0 | AU7: ='Prix des produits et services '!$G$7*'Objectifs de ventes (quantité)'!AU7 -> 0 | AV7: ='Prix des produits et services '!$G$7*'Objectifs de ventes (quantité)'!AV7 -> 0 | AW7: ='Prix des produits et services '!$G$7*'Objectifs de ventes (quantité)'!AW7 -> 0 | ... BA7: ='Prix des produits et services '!$G$7*'Objectifs de ventes (quantité)'!BA7 -> 0 | BB7: =SUM(AP7:BA7) -> 0 | BC7: ='Prix des produits et services '!$H$7*'Objectifs de ventes (quantité)'!BC7 -> 0 | BD7: ='Prix des produits et services '!$H$7*'Objectifs de ventes (quantité)'!BD7 -> 0 | BE7: ='Prix des produits et services '!$H$7*'Objectifs de ventes (quantité)'!BE7 -> 0 | BF7: ='Prix des produits et services '!$H$7*'Objectifs de ventes (quantité)'!BF7 -> 0 | BG7: ='Prix des produits et services '!$H$7*'Objectifs de ventes (quantité)'!BG7 -> 0 | BH7: ='Prix des produits et services '!$H$7*'Objectifs de ventes (quantité)'!BH7 -> 0 | BI7: ='Prix des produits et services '!$H$7*'Objectifs de ventes (quantité)'!BI7 -> 0 | BJ7: ='Prix des produits et services '!$H$7*'Objectifs de ventes (quantité)'!BJ7 -> 0 | ... BN7: ='Prix des produits et services '!$H$7*'Objectifs de ventes (quantité)'!BN7 -> 0 | BO7: =SUM(BC7:BN7) -> 0
A8: ='Prix des produits et services '!B8 -> Produit ou Service 7 | B8: ='Prix des produits et services '!C8 -> 0 | C8: ='Prix des produits et services '!$D$8*'Objectifs de ventes (quantité)'!C8 -> 0 | D8: ='Prix des produits et services '!$D$8*'Objectifs de ventes (quantité)'!D8 -> 0 | E8: ='Prix des produits et services '!$D$8*'Objectifs de ventes (quantité)'!E8 -> 0 | F8: ='Prix des produits et services '!$D$8*'Objectifs de ventes (quantité)'!F8 -> 0 | G8: ='Prix des produits et services '!$D$8*'Objectifs de ventes (quantité)'!G8 -> 0 | H8: ='Prix des produits et services '!$D$8*'Objectifs de ventes (quantité)'!H8 -> 0 | I8: ='Prix des produits et services '!$D$8*'Objectifs de ventes (quantité)'!I8 -> 0 | J8: ='Prix des produits et services '!$D$8*'Objectifs de ventes (quantité)'!J8 -> 0 | ... N8: ='Prix des produits et services '!$D$8*'Objectifs de ventes (quantité)'!N8 -> 0 | O8: =SUM(C8:N8) -> 0 | P8: ='Prix des produits et services '!$E$8*'Objectifs de ventes (quantité)'!P8 -> 0 | Q8: ='Prix des produits et services '!$E$8*'Objectifs de ventes (quantité)'!Q8 -> 0 | R8: ='Prix des produits et services '!$E$8*'Objectifs de ventes (quantité)'!R8 -> 0 | S8: ='Prix des produits et services '!$E$8*'Objectifs de ventes (quantité)'!S8 -> 0 | T8: ='Prix des produits et services '!$E$8*'Objectifs de ventes (quantité)'!T8 -> 0 | U8: ='Prix des produits et services '!$E$8*'Objectifs de ventes (quantité)'!U8 -> 0 | V8: ='Prix des produits et services '!$E$8*'Objectifs de ventes (quantité)'!V8 -> 0 | W8: ='Prix des produits et services '!$E$8*'Objectifs de ventes (quantité)'!W8 -> 0 | ... AA8: ='Prix des produits et services '!$E$8*'Objectifs de ventes (quantité)'!AA8 -> 0 | AB8: =SUM(P8:AA8) -> 0 | AC8: ='Prix des produits et services '!$F$8*'Objectifs de ventes (quantité)'!AC8 -> 0 | AD8: ='Prix des produits et services '!$F$8*'Objectifs de ventes (quantité)'!AD8 -> 0 | AE8: ='Prix des produits et services '!$F$8*'Objectifs de ventes (quantité)'!AE8 -> 0 | AF8: ='Prix des produits et services '!$F$8*'Objectifs de ventes (quantité)'!AF8 -> 0 | AG8: ='Prix des produits et services '!$F$8*'Objectifs de ventes (quantité)'!AG8 -> 0 | AH8: ='Prix des produits et services '!$F$8*'Objectifs de ventes (quantité)'!AH8 -> 0 | AI8: ='Prix des produits et services '!$F$8*'Objectifs de ventes (quantité)'!AI8 -> 0 | AJ8: ='Prix des produits et services '!$F$8*'Objectifs de ventes (quantité)'!AJ8 -> 0 | ... AN8: ='Prix des produits et services '!$F$8*'Objectifs de ventes (quantité)'!AN8 -> 0 | AO8: =SUM(AC8:AN8) -> 0 | AP8: ='Prix des produits et services '!$G$8*'Objectifs de ventes (quantité)'!AP8 -> 0 | AQ8: ='Prix des produits et services '!$G$8*'Objectifs de ventes (quantité)'!AQ8 -> 0 | AR8: ='Prix des produits et services '!$G$8*'Objectifs de ventes (quantité)'!AR8 -> 0 | AS8: ='Prix des produits et services '!$G$8*'Objectifs de ventes (quantité)'!AS8 -> 0 | AT8: ='Prix des produits et services '!$G$8*'Objectifs de ventes (quantité)'!AT8 -> 0 | AU8: ='Prix des produits et services '!$G$8*'Objectifs de ventes (quantité)'!AU8 -> 0 | AV8: ='Prix des produits et services '!$G$8*'Objectifs de ventes (quantité)'!AV8 -> 0 | AW8: ='Prix des produits et services '!$G$8*'Objectifs de ventes (quantité)'!AW8 -> 0 | ... BA8: ='Prix des produits et services '!$G$8*'Objectifs de ventes (quantité)'!BA8 -> 0 | BB8: =SUM(AP8:BA8) -> 0 | BC8: ='Prix des produits et services '!$H$8*'Objectifs de ventes (quantité)'!BC8 -> 0 | BD8: ='Prix des produits et services '!$H$8*'Objectifs de ventes (quantité)'!BD8 -> 0 | BE8: ='Prix des produits et services '!$H$8*'Objectifs de ventes (quantité)'!BE8 -> 0 | BF8: ='Prix des produits et services '!$H$8*'Objectifs de ventes (quantité)'!BF8 -> 0 | BG8: ='Prix des produits et services '!$H$8*'Objectifs de ventes (quantité)'!BG8 -> 0 | BH8: ='Prix des produits et services '!$H$8*'Objectifs de ventes (quantité)'!BH8 -> 0 | BI8: ='Prix des produits et services '!$H$8*'Objectifs de ventes (quantité)'!BI8 -> 0 | BJ8: ='Prix des produits et services '!$H$8*'Objectifs de ventes (quantité)'!BJ8 -> 0 | ... BN8: ='Prix des produits et services '!$H$8*'Objectifs de ventes (quantité)'!BN8 -> 0 | BO8: =SUM(BC8:BN8) -> 0
A9: ='Prix des produits et services '!B9 -> Produit ou Service 8 | B9: ='Prix des produits et services '!C9 -> 0 | C9: ='Prix des produits et services '!$D$9*'Objectifs de ventes (quantité)'!C9 -> 0 | D9: ='Prix des produits et services '!$D$9*'Objectifs de ventes (quantité)'!D9 -> 0 | E9: ='Prix des produits et services '!$D$9*'Objectifs de ventes (quantité)'!E9 -> 0 | F9: ='Prix des produits et services '!$D$9*'Objectifs de ventes (quantité)'!F9 -> 0 | G9: ='Prix des produits et services '!$D$9*'Objectifs de ventes (quantité)'!G9 -> 0 | H9: ='Prix des produits et services '!$D$9*'Objectifs de ventes (quantité)'!H9 -> 0 | I9: ='Prix des produits et services '!$D$9*'Objectifs de ventes (quantité)'!I9 -> 0 | J9: ='Prix des produits et services '!$D$9*'Objectifs de ventes (quantité)'!J9 -> 0 | ... N9: ='Prix des produits et services '!$D$9*'Objectifs de ventes (quantité)'!N9 -> 0 | O9: =SUM(C9:N9) -> 0 | P9: ='Prix des produits et services '!$E$9*'Objectifs de ventes (quantité)'!P9 -> 0 | Q9: ='Prix des produits et services '!$E$9*'Objectifs de ventes (quantité)'!Q9 -> 0 | R9: ='Prix des produits et services '!$E$9*'Objectifs de ventes (quantité)'!R9 -> 0 | S9: ='Prix des produits et services '!$E$9*'Objectifs de ventes (quantité)'!S9 -> 0 | T9: ='Prix des produits et services '!$E$9*'Objectifs de ventes (quantité)'!T9 -> 0 | U9: ='Prix des produits et services '!$E$9*'Objectifs de ventes (quantité)'!U9 -> 0 | V9: ='Prix des produits et services '!$E$9*'Objectifs de ventes (quantité)'!V9 -> 0 | W9: ='Prix des produits et services '!$E$9*'Objectifs de ventes (quantité)'!W9 -> 0 | ... AA9: ='Prix des produits et services '!$E$9*'Objectifs de ventes (quantité)'!AA9 -> 0 | AB9: =SUM(P9:AA9) -> 0 | AC9: ='Prix des produits et services '!$F$9*'Objectifs de ventes (quantité)'!AC9 -> 0 | AD9: ='Prix des produits et services '!$F$9*'Objectifs de ventes (quantité)'!AD9 -> 0 | AE9: ='Prix des produits et services '!$F$9*'Objectifs de ventes (quantité)'!AE9 -> 0 | AF9: ='Prix des produits et services '!$F$9*'Objectifs de ventes (quantité)'!AF9 -> 0 | AG9: ='Prix des produits et services '!$F$9*'Objectifs de ventes (quantité)'!AG9 -> 0 | AH9: ='Prix des produits et services '!$F$9*'Objectifs de ventes (quantité)'!AH9 -> 0 | AI9: ='Prix des produits et services '!$F$9*'Objectifs de ventes (quantité)'!AI9 -> 0 | AJ9: ='Prix des produits et services '!$F$9*'Objectifs de ventes (quantité)'!AJ9 -> 0 | ... AN9: ='Prix des produits et services '!$F$9*'Objectifs de ventes (quantité)'!AN9 -> 0 | AO9: =SUM(AC9:AN9) -> 0 | AP9: ='Prix des produits et services '!$G$9*'Objectifs de ventes (quantité)'!AP9 -> 0 | AQ9: ='Prix des produits et services '!$G$9*'Objectifs de ventes (quantité)'!AQ9 -> 0 | AR9: ='Prix des produits et services '!$G$9*'Objectifs de ventes (quantité)'!AR9 -> 0 | AS9: ='Prix des produits et services '!$G$9*'Objectifs de ventes (quantité)'!AS9 -> 0 | AT9: ='Prix des produits et services '!$G$9*'Objectifs de ventes (quantité)'!AT9 -> 0 | AU9: ='Prix des produits et services '!$G$9*'Objectifs de ventes (quantité)'!AU9 -> 0 | AV9: ='Prix des produits et services '!$G$9*'Objectifs de ventes (quantité)'!AV9 -> 0 | AW9: ='Prix des produits et services '!$G$9*'Objectifs de ventes (quantité)'!AW9 -> 0 | ... BA9: ='Prix des produits et services '!$G$9*'Objectifs de ventes (quantité)'!BA9 -> 0 | BB9: =SUM(AP9:BA9) -> 0 | BC9: ='Prix des produits et services '!$H$9*'Objectifs de ventes (quantité)'!BC9 -> 0 | BD9: ='Prix des produits et services '!$H$9*'Objectifs de ventes (quantité)'!BD9 -> 0 | BE9: ='Prix des produits et services '!$H$9*'Objectifs de ventes (quantité)'!BE9 -> 0 | BF9: ='Prix des produits et services '!$H$9*'Objectifs de ventes (quantité)'!BF9 -> 0 | BG9: ='Prix des produits et services '!$H$9*'Objectifs de ventes (quantité)'!BG9 -> 0 | BH9: ='Prix des produits et services '!$H$9*'Objectifs de ventes (quantité)'!BH9 -> 0 | BI9: ='Prix des produits et services '!$H$9*'Objectifs de ventes (quantité)'!BI9 -> 0 | BJ9: ='Prix des produits et services '!$H$9*'Objectifs de ventes (quantité)'!BJ9 -> 0 | ... BN9: ='Prix des produits et services '!$H$9*'Objectifs de ventes (quantité)'!BN9 -> 0 | BO9: =SUM(BC9:BN9) -> 0
A10: ='Prix des produits et services '!B10 -> Produit ou Service 9 | B10: ='Prix des produits et services '!C10 -> 0 | C10: ='Prix des produits et services '!$D$10*'Objectifs de ventes (quantité)'!C10 -> 0 | D10: ='Prix des produits et services '!$D$10*'Objectifs de ventes (quantité)'!D10 -> 0 | E10: ='Prix des produits et services '!$D$10*'Objectifs de ventes (quantité)'!E10 -> 0 | F10: ='Prix des produits et services '!$D$10*'Objectifs de ventes (quantité)'!F10 -> 0 | G10: ='Prix des produits et services '!$D$10*'Objectifs de ventes (quantité)'!G10 -> 0 | H10: ='Prix des produits et services '!$D$10*'Objectifs de ventes (quantité)'!H10 -> 0 | I10: ='Prix des produits et services '!$D$10*'Objectifs de ventes (quantité)'!I10 -> 0 | J10: ='Prix des produits et services '!$D$10*'Objectifs de ventes (quantité)'!J10 -> 0 | ... N10: ='Prix des produits et services '!$D$10*'Objectifs de ventes (quantité)'!N10 -> 0 | O10: =SUM(C10:N10) -> 0 | P10: ='Prix des produits et services '!$E$10*'Objectifs de ventes (quantité)'!P10 -> 0 | Q10: ='Prix des produits et services '!$E$10*'Objectifs de ventes (quantité)'!Q10 -> 0 | R10: ='Prix des produits et services '!$E$10*'Objectifs de ventes (quantité)'!R10 -> 0 | S10: ='Prix des produits et services '!$E$10*'Objectifs de ventes (quantité)'!S10 -> 0 | T10: ='Prix des produits et services '!$E$10*'Objectifs de ventes (quantité)'!T10 -> 0 | U10: ='Prix des produits et services '!$E$10*'Objectifs de ventes (quantité)'!U10 -> 0 | V10: ='Prix des produits et services '!$E$10*'Objectifs de ventes (quantité)'!V10 -> 0 | W10: ='Prix des produits et services '!$E$10*'Objectifs de ventes (quantité)'!W10 -> 0 | ... AA10: ='Prix des produits et services '!$E$10*'Objectifs de ventes (quantité)'!AA10 -> 0 | AB10: =SUM(P10:AA10) -> 0 | AC10: ='Prix des produits et services '!$F$10*'Objectifs de ventes (quantité)'!AC10 -> 0 | AD10: ='Prix des produits et services '!$F$10*'Objectifs de ventes (quantité)'!AD10 -> 0 | AE10: ='Prix des produits et services '!$F$10*'Objectifs de ventes (quantité)'!AE10 -> 0 | AF10: ='Prix des produits et services '!$F$10*'Objectifs de ventes (quantité)'!AF10 -> 0 | AG10: ='Prix des produits et services '!$F$10*'Objectifs de ventes (quantité)'!AG10 -> 0 | AH10: ='Prix des produits et services '!$F$10*'Objectifs de ventes (quantité)'!AH10 -> 0 | AI10: ='Prix des produits et services '!$F$10*'Objectifs de ventes (quantité)'!AI10 -> 0 | AJ10: ='Prix des produits et services '!$F$10*'Objectifs de ventes (quantité)'!AJ10 -> 0 | ... AN10: ='Prix des produits et services '!$F$10*'Objectifs de ventes (quantité)'!AN10 -> 0 | AO10: =SUM(AC10:AN10) -> 0 | AP10: ='Prix des produits et services '!$G$10*'Objectifs de ventes (quantité)'!AP10 -> 0 | AQ10: ='Prix des produits et services '!$G$10*'Objectifs de ventes (quantité)'!AQ10 -> 0 | AR10: ='Prix des produits et services '!$G$10*'Objectifs de ventes (quantité)'!AR10 -> 0 | AS10: ='Prix des produits et services '!$G$10*'Objectifs de ventes (quantité)'!AS10 -> 0 | AT10: ='Prix des produits et services '!$G$10*'Objectifs de ventes (quantité)'!AT10 -> 0 | AU10: ='Prix des produits et services '!$G$10*'Objectifs de ventes (quantité)'!AU10 -> 0 | AV10: ='Prix des produits et services '!$G$10*'Objectifs de ventes (quantité)'!AV10 -> 0 | AW10: ='Prix des produits et services '!$G$10*'Objectifs de ventes (quantité)'!AW10 -> 0 | ... BA10: ='Prix des produits et services '!$G$10*'Objectifs de ventes (quantité)'!BA10 -> 0 | BB10: =SUM(AP10:BA10) -> 0 | BC10: ='Prix des produits et services '!$H$10*'Objectifs de ventes (quantité)'!BC10 -> 0 | BD10: ='Prix des produits et services '!$H$10*'Objectifs de ventes (quantité)'!BD10 -> 0 | BE10: ='Prix des produits et services '!$H$10*'Objectifs de ventes (quantité)'!BE10 -> 0 | BF10: ='Prix des produits et services '!$H$10*'Objectifs de ventes (quantité)'!BF10 -> 0 | BG10: ='Prix des produits et services '!$H$10*'Objectifs de ventes (quantité)'!BG10 -> 0 | BH10: ='Prix des produits et services '!$H$10*'Objectifs de ventes (quantité)'!BH10 -> 0 | BI10: ='Prix des produits et services '!$H$10*'Objectifs de ventes (quantité)'!BI10 -> 0 | BJ10: ='Prix des produits et services '!$H$10*'Objectifs de ventes (quantité)'!BJ10 -> 0 | ... BN10: ='Prix des produits et services '!$H$10*'Objectifs de ventes (quantité)'!BN10 -> 0 | BO10: =SUM(BC10:BN10) -> 0
A11: ='Prix des produits et services '!B11 -> Produit ou Service 10 | B11: ='Prix des produits et services '!C11 -> 0 | C11: ='Prix des produits et services '!$D$11*'Objectifs de ventes (quantité)'!C11 -> 0 | D11: ='Prix des produits et services '!$D$11*'Objectifs de ventes (quantité)'!D11 -> 0 | E11: ='Prix des produits et services '!$D$11*'Objectifs de ventes (quantité)'!E11 -> 0 | F11: ='Prix des produits et services '!$D$11*'Objectifs de ventes (quantité)'!F11 -> 0 | G11: ='Prix des produits et services '!$D$11*'Objectifs de ventes (quantité)'!G11 -> 0 | H11: ='Prix des produits et services '!$D$11*'Objectifs de ventes (quantité)'!H11 -> 0 | I11: ='Prix des produits et services '!$D$11*'Objectifs de ventes (quantité)'!I11 -> 0 | J11: ='Prix des produits et services '!$D$11*'Objectifs de ventes (quantité)'!J11 -> 0 | ... N11: ='Prix des produits et services '!$D$11*'Objectifs de ventes (quantité)'!N11 -> 0 | O11: =SUM(C11:N11) -> 0 | P11: ='Prix des produits et services '!$E$11*'Objectifs de ventes (quantité)'!P11 -> 0 | Q11: ='Prix des produits et services '!$E$11*'Objectifs de ventes (quantité)'!Q11 -> 0 | R11: ='Prix des produits et services '!$E$11*'Objectifs de ventes (quantité)'!R11 -> 0 | S11: ='Prix des produits et services '!$E$11*'Objectifs de ventes (quantité)'!S11 -> 0 | T11: ='Prix des produits et services '!$E$11*'Objectifs de ventes (quantité)'!T11 -> 0 | U11: ='Prix des produits et services '!$E$11*'Objectifs de ventes (quantité)'!U11 -> 0 | V11: ='Prix des produits et services '!$E$11*'Objectifs de ventes (quantité)'!V11 -> 0 | W11: ='Prix des produits et services '!$E$11*'Objectifs de ventes (quantité)'!W11 -> 0 | ... AA11: ='Prix des produits et services '!$E$11*'Objectifs de ventes (quantité)'!AA11 -> 0 | AB11: =SUM(P11:AA11) -> 0 | AC11: ='Prix des produits et services '!$F$11*'Objectifs de ventes (quantité)'!AC11 -> 0 | AD11: ='Prix des produits et services '!$F$11*'Objectifs de ventes (quantité)'!AD11 -> 0 | AE11: ='Prix des produits et services '!$F$11*'Objectifs de ventes (quantité)'!AE11 -> 0 | AF11: ='Prix des produits et services '!$F$11*'Objectifs de ventes (quantité)'!AF11 -> 0 | AG11: ='Prix des produits et services '!$F$11*'Objectifs de ventes (quantité)'!AG11 -> 0 | AH11: ='Prix des produits et services '!$F$11*'Objectifs de ventes (quantité)'!AH11 -> 0 | AI11: ='Prix des produits et services '!$F$11*'Objectifs de ventes (quantité)'!AI11 -> 0 | AJ11: ='Prix des produits et services '!$F$11*'Objectifs de ventes (quantité)'!AJ11 -> 0 | ... AN11: ='Prix des produits et services '!$F$11*'Objectifs de ventes (quantité)'!AN11 -> 0 | AO11: =SUM(AC11:AN11) -> 0 | AP11: ='Prix des produits et services '!$G$11*'Objectifs de ventes (quantité)'!AP11 -> 0 | AQ11: ='Prix des produits et services '!$G$11*'Objectifs de ventes (quantité)'!AQ11 -> 0 | AR11: ='Prix des produits et services '!$G$11*'Objectifs de ventes (quantité)'!AR11 -> 0 | AS11: ='Prix des produits et services '!$G$11*'Objectifs de ventes (quantité)'!AS11 -> 0 | AT11: ='Prix des produits et services '!$G$11*'Objectifs de ventes (quantité)'!AT11 -> 0 | AU11: ='Prix des produits et services '!$G$11*'Objectifs de ventes (quantité)'!AU11 -> 0 | AV11: ='Prix des produits et services '!$G$11*'Objectifs de ventes (quantité)'!AV11 -> 0 | AW11: ='Prix des produits et services '!$G$11*'Objectifs de ventes (quantité)'!AW11 -> 0 | ... BA11: ='Prix des produits et services '!$G$11*'Objectifs de ventes (quantité)'!BA11 -> 0 | BB11: =SUM(AP11:BA11) -> 0 | BC11: ='Prix des produits et services '!$H$11*'Objectifs de ventes (quantité)'!BC11 -> 0 | BD11: ='Prix des produits et services '!$H$11*'Objectifs de ventes (quantité)'!BD11 -> 0 | BE11: ='Prix des produits et services '!$H$11*'Objectifs de ventes (quantité)'!BE11 -> 0 | BF11: ='Prix des produits et services '!$H$11*'Objectifs de ventes (quantité)'!BF11 -> 0 | BG11: ='Prix des produits et services '!$H$11*'Objectifs de ventes (quantité)'!BG11 -> 0 | BH11: ='Prix des produits et services '!$H$11*'Objectifs de ventes (quantité)'!BH11 -> 0 | BI11: ='Prix des produits et services '!$H$11*'Objectifs de ventes (quantité)'!BI11 -> 0 | BJ11: ='Prix des produits et services '!$H$11*'Objectifs de ventes (quantité)'!BJ11 -> 0 | ... BN11: ='Prix des produits et services '!$H$11*'Objectifs de ventes (quantité)'!BN11 -> 0 | BO11: =SUM(BC11:BN11) -> 0
A12: ='Prix des produits et services '!B12 -> Produit ou Service 11 | B12: ='Prix des produits et services '!C12 -> 0 | C12: ='Prix des produits et services '!$D$12*'Objectifs de ventes (quantité)'!C12 -> 0 | D12: ='Prix des produits et services '!$D$12*'Objectifs de ventes (quantité)'!D12 -> 0 | E12: ='Prix des produits et services '!$D$12*'Objectifs de ventes (quantité)'!E12 -> 0 | F12: ='Prix des produits et services '!$D$12*'Objectifs de ventes (quantité)'!F12 -> 0 | G12: ='Prix des produits et services '!$D$12*'Objectifs de ventes (quantité)'!G12 -> 0 | H12: ='Prix des produits et services '!$D$12*'Objectifs de ventes (quantité)'!H12 -> 0 | I12: ='Prix des produits et services '!$D$12*'Objectifs de ventes (quantité)'!I12 -> 0 | J12: ='Prix des produits et services '!$D$12*'Objectifs de ventes (quantité)'!J12 -> 0 | ... N12: ='Prix des produits et services '!$D$12*'Objectifs de ventes (quantité)'!N12 -> 0 | O12: =SUM(C12:N12) -> 0 | P12: ='Prix des produits et services '!$E$12*'Objectifs de ventes (quantité)'!P12 -> 0 | Q12: ='Prix des produits et services '!$E$12*'Objectifs de ventes (quantité)'!Q12 -> 0 | R12: ='Prix des produits et services '!$E$12*'Objectifs de ventes (quantité)'!R12 -> 0 | S12: ='Prix des produits et services '!$E$12*'Objectifs de ventes (quantité)'!S12 -> 0 | T12: ='Prix des produits et services '!$E$12*'Objectifs de ventes (quantité)'!T12 -> 0 | U12: ='Prix des produits et services '!$E$12*'Objectifs de ventes (quantité)'!U12 -> 0 | V12: ='Prix des produits et services '!$E$12*'Objectifs de ventes (quantité)'!V12 -> 0 | W12: ='Prix des produits et services '!$E$12*'Objectifs de ventes (quantité)'!W12 -> 0 | ... AA12: ='Prix des produits et services '!$E$12*'Objectifs de ventes (quantité)'!AA12 -> 0 | AB12: =SUM(P12:AA12) -> 0 | AC12: ='Prix des produits et services '!$F$12*'Objectifs de ventes (quantité)'!AC12 -> 0 | AD12: ='Prix des produits et services '!$F$12*'Objectifs de ventes (quantité)'!AD12 -> 0 | AE12: ='Prix des produits et services '!$F$12*'Objectifs de ventes (quantité)'!AE12 -> 0 | AF12: ='Prix des produits et services '!$F$12*'Objectifs de ventes (quantité)'!AF12 -> 0 | AG12: ='Prix des produits et services '!$F$12*'Objectifs de ventes (quantité)'!AG12 -> 0 | AH12: ='Prix des produits et services '!$F$12*'Objectifs de ventes (quantité)'!AH12 -> 0 | AI12: ='Prix des produits et services '!$F$12*'Objectifs de ventes (quantité)'!AI12 -> 0 | AJ12: ='Prix des produits et services '!$F$12*'Objectifs de ventes (quantité)'!AJ12 -> 0 | ... AN12: ='Prix des produits et services '!$F$12*'Objectifs de ventes (quantité)'!AN12 -> 0 | AO12: =SUM(AC12:AN12) -> 0 | AP12: ='Prix des produits et services '!$G$12*'Objectifs de ventes (quantité)'!AP12 -> 0 | AQ12: ='Prix des produits et services '!$G$12*'Objectifs de ventes (quantité)'!AQ12 -> 0 | AR12: ='Prix des produits et services '!$G$12*'Objectifs de ventes (quantité)'!AR12 -> 0 | AS12: ='Prix des produits et services '!$G$12*'Objectifs de ventes (quantité)'!AS12 -> 0 | AT12: ='Prix des produits et services '!$G$12*'Objectifs de ventes (quantité)'!AT12 -> 0 | AU12: ='Prix des produits et services '!$G$12*'Objectifs de ventes (quantité)'!AU12 -> 0 | AV12: ='Prix des produits et services '!$G$12*'Objectifs de ventes (quantité)'!AV12 -> 0 | AW12: ='Prix des produits et services '!$G$12*'Objectifs de ventes (quantité)'!AW12 -> 0 | ... BA12: ='Prix des produits et services '!$G$12*'Objectifs de ventes (quantité)'!BA12 -> 0 | BB12: =SUM(AP12:BA12) -> 0 | BC12: ='Prix des produits et services '!$H$12*'Objectifs de ventes (quantité)'!BC12 -> 0 | BD12: ='Prix des produits et services '!$H$12*'Objectifs de ventes (quantité)'!BD12 -> 0 | BE12: ='Prix des produits et services '!$H$12*'Objectifs de ventes (quantité)'!BE12 -> 0 | BF12: ='Prix des produits et services '!$H$12*'Objectifs de ventes (quantité)'!BF12 -> 0 | BG12: ='Prix des produits et services '!$H$12*'Objectifs de ventes (quantité)'!BG12 -> 0 | BH12: ='Prix des produits et services '!$H$12*'Objectifs de ventes (quantité)'!BH12 -> 0 | BI12: ='Prix des produits et services '!$H$12*'Objectifs de ventes (quantité)'!BI12 -> 0 | BJ12: ='Prix des produits et services '!$H$12*'Objectifs de ventes (quantité)'!BJ12 -> 0 | ... BN12: ='Prix des produits et services '!$H$12*'Objectifs de ventes (quantité)'!BN12 -> 0 | BO12: =SUM(BC12:BN12) -> 0
